Workbook

Sheet Thong_tin
A1: BỘ BIỂU MẪU KIỂM THỬ – VAI TESTER
A2: Học phần Đánh giá hiệu năng · Dùng cho hệ thống của bạn cặp
A4: Tester – Họ và tên
A5: Tester – MSSV
A6: Hệ thống được kiểm thử
A7: Chủ hệ thống – Họ tên, MSSV
A8: Link sản phẩm
A9: Phiên bản SRS dùng làm căn cứ
A10: Thời gian kiểm thử (từ – đến)
A12: CÁC SHEET TRONG FILE
A13: Review_SRS | B13: Phiếu review SRS (tuần 5). Chủ hệ thống điền 2 cột phản hồi cuối.
A14: TC_Chuc_nang | B14: Test case chức năng, luồng E2E và phân quyền. Tối thiểu 60 case, phủ hết chức năng và 3 luồng.
A15: TC_Phi_chuc_nang | B15: Test case phi chức năng. Tối thiểu 10 case, phủ hết NFR trong SRS.
A16: Test_Log | B16: Nhật ký mỗi phiên thực thi: thời gian, môi trường, phạm vi đã chạy, kết quả.
A17: Bug_Report | B17: Danh sách lỗi. Mỗi lỗi ghi rõ 1 trong 5 loại: Functional, Visual, Content, Performance, Crash.
A18: Tong_hop | B18: Tự tính số liệu để đưa vào Test Summary Report. Không cần điền.
A20: Chú thích: ô nền vàng nhạt = sinh viên điền; dòng chữ xám nghiêng ở đầu mỗi bảng = VÍ DỤ, ghi đè hoặc xoá khi làm; cột có mũi tên = chọn từ danh sách.

Sheet Review_SRS
A1: PHIẾU REVIEW SRS
A2: Tester kiểm tra từng yêu cầu: rõ ràng? kiểm thử được? đầy đủ? nhất quán? Chủ hệ thống điền 2 cột cuối rồi cập nhật SRS.
A3: Chú thích: ô nền vàng nhạt = sinh viên điền; dòng chữ xám nghiêng = VÍ DỤ, ghi đè hoặc xoá khi làm; cột có mũi tên = chọn từ danh sách.
A4: STT | B4: Vị trí trong SRS (mục / mã yêu cầu) | C4: Nội dung trích từ SRS | D4: Vấn đề phát hiện | E4: Loại vấn đề | F4: Mức độ | G4: Đề xuất sửa | H4: Phản hồi của chủ hệ thống | I4: Lý do / cách đã sửa
A5: 1 | B5: FR-03 – trường Mật khẩu | C5: "Mật khẩu phải đủ mạnh" | D5: Không có tiêu chí cụ thể nên không viết được test case giá trị biên | E5: Không kiểm thử được | F5: Cao | G5: Ghi rõ: 8–32 ký tự, có ít nhất 1 chữ hoa, 1 chữ thường, 1 chữ số | H5: Chấp nhận | I5: Đã sửa ở SRS v1.1, mục 4.3

Sheet TC_Chuc_nang
A1: TEST CASE CHỨC NĂNG
A2: Quy ước mã: TC-FRxx-nnn (chức năng) · TC-FLOWxx-nnn (luồng E2E) · TC-AUTHZ-nnn (phân quyền). Mỗi chức năng ≥ 3 case.
A3: Chú thích: ô nền vàng nhạt = sinh viên điền; dòng chữ xám nghiêng = VÍ DỤ, ghi đè hoặc xoá khi làm; cột có mũi tên = chọn từ danh sách.
A4: TC ID | B4: Chức năng / Luồng | C4: Kỹ thuật thiết kế | D4: Tiêu đề | E4: Tiền điều kiện | F4: Dữ liệu thử | G4: Các bước thực hiện | H4: Kết quả mong đợi | I4: Độ ưu tiên | J4: Kết quả | K4: Kết quả thực tế (khi Fail) | L4: Bug ID | M4: Ghi chú
A5: TC-FR06-004 | B5: FR-06 | C5: Giá trị biên (BVA) | D5: Đặt phòng với số khách = 11 (vượt biên trên) | E5: Đã đăng nhập vai Thành viên; phòng P101 còn trống | F5: Số khách = 11 | G5: 1. Mở trang Đặt phòng P101 2. Nhập Số khách = 11 3. Bấm Đặt phòng | H5: Hiển thị "Số khách từ 1 đến 10", không tạo đơn | I5: High | J5: Fail | K5: Tạo đơn thành công với 11 khách | L5: BUG-007

Sheet TC_Phi_chuc_nang
A1: TEST CASE PHI CHỨC NĂNG
A2: Quy ước mã: TC-NFRxx-nnn. Mỗi NFR trong SRS có ít nhất 1 case. Ngưỡng đạt lấy đúng theo SRS.
A3: Chú thích: ô nền vàng nhạt = sinh viên điền; dòng chữ xám nghiêng = VÍ DỤ, ghi đè hoặc xoá khi làm; cột có mũi tên = chọn từ danh sách.
A4: TC ID | B4: Mã NFR | C4: Nhóm | D4: Tiêu đề | E4: Công cụ / phương pháp | F4: Điều kiện / môi trường | G4: Các bước thực hiện | H4: Ngưỡng đạt (theo SRS) | I4: Giá trị đo được | J4: Kết quả | K4: Bug ID | L4: Ghi chú
A5: TC-NFR01-001 | B5: NFR-01 | C5: Hiệu năng | D5: Thời gian phản hồi FLOW-01 với 20 người dùng đồng thời | E5: JMeter (non-GUI) | F5: Server được cấp; 20 thread, ramp-up 60 s, chạy 5 phút | G5: 1. Chạy plan.jmx với 20 thread 2. Sinh HTML dashboard 3. Đọc P90 và tỉ lệ lỗi | H5: P90 ≤ 2 s; tỉ lệ lỗi < 1% | I5: P90 = 3,4 s; lỗi 0,2% | J5: Fail | K5: BUG-015

Sheet Test_Log
A1: NHẬT KÝ THỰC THI KIỂM THỬ (TEST LOG)
A2: Mỗi phiên chạy test ghi 1 dòng. Ghi cả sự cố môi trường (link không truy cập được, dữ liệu bị reset…).
A3: Chú thích: ô nền vàng nhạt = sinh viên điền; dòng chữ xám nghiêng = VÍ DỤ, ghi đè hoặc xoá khi làm; cột có mũi tên = chọn từ danh sách.
A4: STT | B4: Ngày | C4: Giờ (bắt đầu – kết thúc) | D4: Link / phiên bản | E4: Trình duyệt / thiết bị | F4: Phạm vi đã chạy (TC ID) | G4: Số TC chạy | H4: Pass | I4: Fail | J4: Blocked | K4: Bug mới (ID) | L4: Sự cố / ghi chú
A5: 1 | B5: 12/10/2026 | C5: 19:00 – 21:30 | D5: https://sv123.demo.edu.vn | E5: Chrome 129 / Windows 11 | F5: TC-FR01-001 → TC-FR06-010 | G5: 38 | H5: 31 | I5: 6 | J5: 1 | K5: BUG-001 → BUG-006 | L5: TC-FR05-003 bị chặn do trang thanh toán trả lỗi 500 (BUG-004)

Sheet Bug_Report
A1: DANH SÁCH BUG REPORT
A2: Mỗi lỗi có bằng chứng (link ảnh / video) và ghi rõ yêu cầu SRS bị vi phạm. Chủ hệ thống điền 2 cột cuối.
A3: Chú thích: ô nền vàng nhạt = sinh viên điền; dòng chữ xám nghiêng = VÍ DỤ, ghi đè hoặc xoá khi làm; cột có mũi tên = chọn từ danh sách.
A4: Bug ID | B4: Tiêu đề | C4: Loại lỗi | D4: Mức nghiêm trọng | E4: Mức ưu tiên | F4: Chức năng / NFR | G4: TC liên quan | H4: URL / màn hình | I4: Trình duyệt / thiết bị | J4: Tiền điều kiện | K4: Các bước tái hiện | L4: Kết quả thực tế | M4: Kết quả mong đợi (trích SRS) | N4: Bằng chứng (link) | O4: Ngày phát hiện | P4: Trạng thái | Q4: Phản hồi của chủ hệ thống
A5: BUG-007 | B5: Đặt phòng thành công với số khách = 11, vượt giới hạn 10 | C5: Functional | D5: Major | E5: High | F5: FR-06 | G5: TC-FR06-004 | H5: /booking/P101 | I5: Chrome 129 / Windows 11 | J5: Đăng nhập member01; phòng P101 còn trống | K5: 1. Mở /booking/P101 2. Nhập Số khách = 11 3. Bấm Đặt phòng | L5: Tạo đơn BK-20261012-0003 với 11 khách | M5: FR-06: "Số khách là số nguyên từ 1 đến 10"; báo lỗi và không tạo đơn | N5: drive.google.com/…/bug007.png | O5: 12/10/2026 | P5: Mới

Sheet Tong_hop
A1: TỔNG HỢP SỐ LIỆU (TỰ ĐỘNG)
A2: Không cần điền. Dùng các số liệu này cho Test Summary Report.
A4: 1. Kiểm tra số lượng tối thiểu | B4: Hiện có | C4: Tối thiểu | D4: Trạng thái
A5: Test case chức năng | B5: =COUNTA(TC_Chuc_nang!$A$5:$A$500) -> 1 | C5: 60 | D5: =IF(B5>=C5,"Đạt","Chưa đạt") -> Chưa đạt
A6: Test case phi chức năng | B6: =COUNTA(TC_Phi_chuc_nang!$A$5:$A$500) -> 1 | C6: 10 | D6: =IF(B6>=C6,"Đạt","Chưa đạt") -> Chưa đạt
A7: Test case luồng E2E (Use case / E2E) | B7: =COUNTIF(TC_Chuc_nang!$C$5:$C$500,"Use case / E2E") -> 0 | C7: 9 | D7: =IF(B7>=C7,"Đạt","Chưa đạt") -> Chưa đạt
A8: Số kỹ thuật thiết kế đã dùng | B8: =COUNTIF(B36:B43,">0") -> 1 | C8: 4 | D8: =IF(B8>=C8,"Đạt","Chưa đạt") -> Chưa đạt
A9: Ghi chú: dòng ví dụ ở đầu mỗi sheet cũng được đếm, hãy ghi đè hoặc xoá trước khi nộp.
A11: 2. Kết quả thực thi | B11: Chức năng | C11: Phi chức năng | D11: Tổng
A12: Tổng số test case | B12: =COUNTA(TC_Chuc_nang!$A$5:$A$500) -> 1 | C12: =COUNTA(TC_Phi_chuc_nang!$A$5:$A$500) -> 1 | D12: =B12+C12 -> 2
A13: Pass | B13: =COUNTIF(TC_Chuc_nang!$J$5:$J$500,"Pass") -> 0 | C13: =COUNTIF(TC_Phi_chuc_nang!$J$5:$J$500,"Pass") -> 0 | D13: =B13+C13 -> 0
A14: Fail | B14: =COUNTIF(TC_Chuc_nang!$J$5:$J$500,"Fail") -> 1 | C14: =COUNTIF(TC_Phi_chuc_nang!$J$5:$J$500,"Fail") -> 1 | D14: =B14+C14 -> 2
A15: Blocked | B15: =COUNTIF(TC_Chuc_nang!$J$5:$J$500,"Blocked") -> 0 | C15: =COUNTIF(TC_Phi_chuc_nang!$J$5:$J$500,"Blocked") -> 0 | D15: =B15+C15 -> 0
A16: Chưa chạy | B16: =COUNTIF(TC_Chuc_nang!$J$5:$J$500,"Chưa chạy") -> 0 | C16: =COUNTIF(TC_Phi_chuc_nang!$J$5:$J$500,"Chưa chạy") -> 0 | D16: =B16+C16 -> 0
A17: Đã thực thi | B17: =B13+B14+B15 -> 1 | C17: =C13+C14+C15 -> 1 | D17: =B17+C17 -> 2
A18: Tỉ lệ Pass / đã thực thi | B18: =IF(B17=0,"",B13/B17) -> 0 | C18: =IF(C17=0,"",C13/C17) -> 0 | D18: =IF(D17=0,"",D13/D17) -> 0
A20: 3. Bug theo loại lỗi | B20: Critical | C20: Major | D20: Minor | E20: Trivial | F20: Tổng
A21: Functional | B21: =COUNTIFS(Bug_Report!$C$5:$C$500,$A21,Bug_Report!$D$5:$D$500,B$20) -> 0 | C21: =COUNTIFS(Bug_Report!$C$5:$C$500,$A21,Bug_Report!$D$5:$D$500,C$20) -> 1 | D21: =COUNTIFS(Bug_Report!$C$5:$C$500,$A21,Bug_Report!$D$5:$D$500,D$20) -> 0 | E21: =COUNTIFS(Bug_Report!$C$5:$C$500,$A21,Bug_Report!$D$5:$D$500,E$20) -> 0 | F21: =SUM(B21:E21) -> 1
A22: Visual | B22: =COUNTIFS(Bug_Report!$C$5:$C$500,$A22,Bug_Report!$D$5:$D$500,B$20) -> 0 | C22: =COUNTIFS(Bug_Report!$C$5:$C$500,$A22,Bug_Report!$D$5:$D$500,C$20) -> 0 | D22: =COUNTIFS(Bug_Report!$C$5:$C$500,$A22,Bug_Report!$D$5:$D$500,D$20) -> 0 | E22: =COUNTIFS(Bug_Report!$C$5:$C$500,$A22,Bug_Report!$D$5:$D$500,E$20) -> 0 | F22: =SUM(B22:E22) -> 0
A23: Content | B23: =COUNTIFS(Bug_Report!$C$5:$C$500,$A23,Bug_Report!$D$5:$D$500,B$20) -> 0 | C23: =COUNTIFS(Bug_Report!$C$5:$C$500,$A23,Bug_Report!$D$5:$D$500,C$20) -> 0 | D23: =COUNTIFS(Bug_Report!$C$5:$C$500,$A23,Bug_Report!$D$5:$D$500,D$20) -> 0 | E23: =COUNTIFS(Bug_Report!$C$5:$C$500,$A23,Bug_Report!$D$5:$D$500,E$20) -> 0 | F23: =SUM(B23:E23) -> 0
A24: Performance | B24: =COUNTIFS(Bug_Report!$C$5:$C$500,$A24,Bug_Report!$D$5:$D$500,B$20) -> 0 | C24: =COUNTIFS(Bug_Report!$C$5:$C$500,$A24,Bug_Report!$D$5:$D$500,C$20) -> 0 | D24: =COUNTIFS(Bug_Report!$C$5:$C$500,$A24,Bug_Report!$D$5:$D$500,D$20) -> 0 | E24: =COUNTIFS(Bug_Report!$C$5:$C$500,$A24,Bug_Report!$D$5:$D$500,E$20) -> 0 | F24: =SUM(B24:E24) -> 0
A25: Crash | B25: =COUNTIFS(Bug_Report!$C$5:$C$500,$A25,Bug_Report!$D$5:$D$500,B$20) -> 0 | C25: =COUNTIFS(Bug_Report!$C$5:$C$500,$A25,Bug_Report!$D$5:$D$500,C$20) -> 0 | D25: =COUNTIFS(Bug_Report!$C$5:$C$500,$A25,Bug_Report!$D$5:$D$500,D$20) -> 0 | E25: =COUNTIFS(Bug_Report!$C$5:$C$500,$A25,Bug_Report!$D$5:$D$500,E$20) -> 0 | F25: =SUM(B25:E25) -> 0
A26: Tổng | B26: =SUM(B21:B25) -> 0 | C26: =SUM(C21:C25) -> 1 | D26: =SUM(D21:D25) -> 0 | E26: =SUM(E21:E25) -> 0 | F26: =SUM(F21:F25) -> 1
A28: 4. Bug theo trạng thái phản hồi | B28: Số lượng
A29: Mới | B29: =COUNTIF(Bug_Report!$P$5:$P$500,A29) -> 1
A30: Đã xác nhận | B30: =COUNTIF(Bug_Report!$P$5:$P$500,A30) -> 0
A31: Bị từ chối | B31: =COUNTIF(Bug_Report!$P$5:$P$500,A31) -> 0
A32: Trùng lặp | B32: =COUNTIF(Bug_Report!$P$5:$P$500,A32) -> 0
A33: Cần thêm thông tin | B33: =COUNTIF(Bug_Report!$P$5:$P$500,A33) -> 0
A35: 5. Test case theo kỹ thuật | B35: Số lượng
A36: Phân hoạch tương đương (EP) | B36: =COUNTIF(TC_Chuc_nang!$C$5:$C$500,A36) -> 0
A37: Giá trị biên (BVA) | B37: =COUNTIF(TC_Chuc_nang!$C$5:$C$500,A37) -> 1
A38: Bảng quyết định | B38: =COUNTIF(TC_Chuc_nang!$C$5:$C$500,A38) -> 0
A39: Chuyển trạng thái | B39: =COUNTIF(TC_Chuc_nang!$C$5:$C$500,A39) -> 0
A40: Use case / E2E | B40: =COUNTIF(TC_Chuc_nang!$C$5:$C$500,A40) -> 0
A41: Phân quyền | B41: =COUNTIF(TC_Chuc_nang!$C$5:$C$500,A41) -> 0
A42: Error guessing / Checklist | B42: =COUNTIF(TC_Chuc_nang!$C$5:$C$500,A42) -> 0
A43: Exploratory | B43: =COUNTIF(TC_Chuc_nang!$C$5:$C$500,A43) -> 0
A45: 6. Review SRS | B45: Số lượng
A46: Tổng số vấn đề đã nêu | B46: =COUNTA(Review_SRS!$D$5:$D$500) -> 1
...
